Workbook
Name _C1: Hoja3!$A$2:$A$7
Name _C10: Hoja3!$J$2:$J$9
Name _C11: Hoja3!$K$2:$K$7
Name _C12: Hoja3!$L$2:$L$3
Name _C13: Hoja3!$M$2:$M$5
Name _C14: Hoja3!$N$2:$N$4
Name _C15: Hoja3!$O$2:$O$6
Name _C16: Hoja3!$P$2:$P$11
Name _C17: Hoja3!$Q$2:$Q$11
Name _C18: Hoja3!$R$2:$R$4
Name _C19: Hoja3!$S$2:$S$15
Name _C2: Hoja3!$B$2:$B$5
Name _C20: Hoja3!$T$2:$T$7
Name _C21: Hoja3!$U$2:$U$6
Name _C22: Hoja3!$V$2:$V$5
Name _C23: Hoja3!$W$2:$W$9
Name _C24: Hoja3!$X$2:$X$6
Name _C25: Hoja3!$Y$2:$Y$5
Name _C26: Hoja3!$Z$2:$Z$3
Name _C27: Hoja3!$AA$2:$AA$10
Name _C28: Hoja3!$AB$2:$AB$9
Name _C29: Hoja3!$AC$2:$AC$12
Name _C3: Hoja3!$C$2:$C$10
Name _C30: Hoja3!$AD$2:$AD$9
Name _C31: Hoja3!$AE$2:$AE$10
Name _C32: Hoja3!$AF$2:$AF$4
Name _C33: Hoja3!$AG$2:$AG$8
Name _C34: Hoja3!$AH$2:$AH$3
Name _C35: Hoja3!$AI$2:$AI$5
Name _C36: Hoja3!$AJ$2:$AJ$9
Name _C37: Hoja3!$AK$2:$AK$5
Name _C38: Hoja3!$AL$2:$AL$6
Name _C39: Hoja3!$AM$2:$AM$9
Name _C4: Hoja3!$D$2:$D$5
Name _C40: Hoja3!$AN$2:$AN$6
Name _C5: Hoja3!$E$2:$E$8
Name _C6: Hoja3!$F$2:$F$4
Name _C7: Hoja3!$G$2:$G$6
Name _C8: Hoja3!$H$2:$H$4
Name _C9: Hoja3!$I$2:$I$7
Name Accion_Evangelizadora: Hoja2!$O$40
Name Actualizar_oferta_de_programas: Hoja2!$J$40:$J$43
Name Articular_Modelo_De_Autoevaluacion: Hoja2!$G$40:$G$41
Name Asp_C1: Listas!$O$4:$O$4
Name Asp_C10: Listas!$X$4:$X$10
Name Asp_C11: Listas!$Y$4:$Y$6
Name Asp_C12: Listas!$Z$4:$Z$5
Name Asp_C13: Listas!$AA$4:$AA$6
Name Asp_C14: Listas!$AB$4:$AB$4
Name Asp_C15: Listas!$AC$4:$AC$5
Name Asp_C16: Listas!$AD$4:$AD$5
Name Asp_C17: Listas!$AE$4:$AE$5
Name Asp_C18: Listas!$AF$4:$AF$5
Name Asp_C19: Listas!$AG$4:$AG$5
Name Asp_C2: Listas!$P$4:$P$6
Name Asp_C20: Listas!$AH$4:$AH$5
Name Asp_C21: Listas!$AI$4:$AI$6
Name Asp_C22: Listas!$AJ$4:$AJ$6
Name Asp_C23: Listas!$AK$4:$AK$5
Name Asp_C24: Listas!$AL$4:$AL$4

Sheet Listas
A1: LISTAS PARA DESPLEGABLES (NO BORRAR ESTA HOJA)
A3: FACTORES | C3: F1 | D3: F2 | E3: F3 | F3: F4 | G3: F5 | H3: F6 | I3: F7 | J3: F8 | K3: F9 | L3: F10 | M3: F11 | N3: F12 | O3: C1 | P3: C2 | Q3: C3 | R3: C4 | S3: C5 | T3: C6 | U3: C7 | V3: C8 | W3: C9 | X3: C10 | Y3: C11 | Z3: C12 | AA3: C13 | AB3: C14 | AC3: C15 | AD3: C16 | AE3: C17 | AF3: C18 | AG3: C19 | AH3: C20 | AI3: C21 | AJ3: C22 | AK3: C23 | AL3: C24 | AM3: C25 | AN3: C26 | AO3: C27 | AP3: C28 | AQ3: C29 | AR3: C30 | AS3: C31 | AT3: C32 | AU3: C33 | AV3: C34 | AW3: C35 | AX3: C36 | AY3: C37 | AZ3: C38 | BA3: C39 | BB3: C40 | BC3: C41 | BD3: C42 | BE3: C43 | BF3: C44 | BG3: C45 | BH3: C46 | BI3: C47 | BJ3: C48 | BL3: Tipo de acción | BM3: PROCESO RESPONSABLE | BO3: OBJETIVOS | BP3: OE1_Diseñar e implementar estrategias integrales e innovadoras para arraigar la identidad de UNICESMAG | BQ3: OE2_Articular las labores institucionales desde una óptica transformadora de la persona para impactar la sociedad desde el reconocimiento de las culturas y las comunidades | BR3: OE3_Desarrollar una arquitectura institucional bajo los principios de ética y buen gobierno
A4: F1. Proyecto Educativo del Programa e Identidad Institucional | C4: C1. Proyecto Educativo del Programa | D4: C3. Participación en actividades de formación integral | E4: C8. Selección, vinculación y permanencia | F4: C16. Seguimiento de los egresados | G4: C18. Integralidad de los aspectos curriculares | H4: C27. Políticas, estrategias y estructura para la permanencia y la graduación | I4: C31. Inserción del programa en contextos académicos nacionales e internacionales | J4: C34. Formación para la investigación, desarrollo tecnológico, la innovación y la creación | K4: C36. Programas y servicios | L4: C38. Estrategias y recursos de apoyo a profesores | M4: C41. Organización y administración | N4: C47. Recursos de infraestructura física y tecnológica. | O4: A1. Demostrar coherencia del Proyecto Educativo del Programa (PEP) o el que haga sus veces, con los lineamientos y políticas Institucionales, así como en la definición de objetivos de formación y resultados de aprendizaje y la manera cómo el PEP ha ido mejorando, como resultado de los procesos de aseguramiento de la calidad, la consolidación de la identidad Institucional y la relación que mantiene con la comunidad y sus grupos de interés. | P4: A2. Análisis sobre las tendencias, necesidades y líneas de desarrollo de la disciplina o profesión, en el contexto regional, nacional e internacional. | Q4: A5. Apreciación de los estudiantes en relación con su participación en las actividades de investigación, desarrollo tecnológico, creación artística, culturales, deportivas y de extensión, que contribuyen a su formación integral, junto con las acciones emprendidas como resultado de dichas apreciaciones. | R4: A9. Evidencia de los efectos en la formación de los estudiantes, a partir de los procesos de orientación y seguimiento de los estudiantes, teniendo como referencia sus características de ingreso. | S4: A10. Evidencia de los resultados de las estrategias de seguimiento y evaluación de los resultados de aprendizaje en el desarrollo de capacidades para el trabajo autónomo del estudiante. | T4: A11. Apreciación de estudiantes y profesores del programa sobre la pertinencia, vigencia y aplicación del reglamento estudiantil y las políticas académicas y, sobre las estrategias de divulgación de dicha reglamentación, junto con las acciones emprendidas como resultado de dichas apreciaciones. | U4: A13. Evidencia de los beneficios generados por el otorgamiento de estímulos académicos y apoyos socioeconómicos a los estudiantes. | V4: A15. Evidencia de la aplicación de los procesos de selección, vinculación y permanencia de los profesores, en coherencia con el nivel de formación, modalidad del programa académico y lugar de desarrollo. | W4: A17. Evidencias que demuestren los resultados de la aplicación del estatuto profesoral, o el que haga sus veces, sobre la trayectoria profesoral, la inclusión, el reconocimiento de méritos y el ascenso en el escalafón, de acuerdo con el nivel de formación y la modalidad del programa. | X4: A20. Evidencia de la coherencia entre el número, dedicación, nivel de formación y experiencia de los profesores de tiempo completo, con el número de estudiantes, nivel de formación y modalidad del programa académico. | Y4: A27. Análisis de los resultados de la aplicación de políticas y estrategias Institucionales en materia de desarrollo integral del profesorado, que incluya la capacitación y la actualización en los aspectos académicos, profesionales y pedagógicos relacionados con la naturaleza, nivel de formación y modalidad del programa. | Z4: A30. Evidencia de los efectos generados en el desempeño de las labores de docencia, investigación y extensión con el otorgamiento de estímulos a los profesores. | AA4: A32. Evidencia de la efectividad de los criterios de evaluación del material producido por los profesores en la calidad de los aprendizajes de los estudiantes, de acuerdo con el nivel de formación y modalidad del programa académico. | AB4: A35. La remuneración que reciben los profesores está de acuerdo con sus méritos académicos y profesionales, el aporte en el desarrollo de los componentes formativos, pedagógicos y de evaluación, la interacción y relevancia social, el nivel de formación y la modalidad del programa académico. | AC4: A36. Apreciación de los profesores, directivos y estudiantes sobre los criterios y mecanismos para la evaluación de los profesores; su transparencia, equidad y eficacia y; su coherencia con la naturaleza de la institución, el nivel de formación y la modalidad del programa, junto con las acciones emprendidas como resultado de dichas apreciaciones. | AD4: A38. Resultado de los estudios sistémicos aplicados sobre el desarrollo profesional y laboral de los egresados, el alcance de las competencias adquiridas, la correspondencia entre el desempeño de los egresados y el perfil de egreso o resultados de aprendizaje del programa. | AE4: A40. Evidencia del impacto de los egresados en el medio social y académico, científico y cultural, como un mecanismo para establecer los aportes del programa a la solución de problemas de la sociedad y/o la creación e innovación de conocimiento. | AF4: A42. Resultados de la aplicación de ejercicios continuos de evaluación de la integralidad del currículo que conduzcan a la realización de ajustes y mejoras que impactan a la formación en valores, actitudes, aptitudes, conocimientos, métodos, capacidades y habilidades, de acuerdo con el estado del arte y con el ejercicio de la disciplina, profesión, ocupación u oficio, y que busca la formación integral del estudiante en coherencia con la misión Institucional y los objetivos propios del programa académico. | AG4: A44. Evidencia de procesos de flexibilización como, doble titulación; articulación pregrado-posgrado; reconocimiento de créditos, homologación y oferta de cursos electivos en distintas modalidades y lugares de desarrollo entre otros, que permiten al estudiante interactuar con otros programas a nivel I, nacional e internacional. | AH4: A46. Evidencia de la implementación de las estrategias que promueven y estimulan la interdisciplinariedad curricular del programa, y el resultado de su aplicación en las diferentes rutas formativas seguidas por los estudiantes. | AI4: A48. Apreciación de profesores y estudiantes sobre la coherencia de las estrategias pedagógicas utilizadas que facilitan el logro de los resultados de aprendizaje esperados, incluyendo los escenarios de práctica para los programas que lo requieren, valorando la calidad, la pertinencia, el acompañamiento y el cumplimiento de la normatividad específica para su desarrollo, junto con las acciones emprendidas como resultado de dichas apreciaciones. | AJ4: A51. Apreciación de profesores y estudiantes sobre los sistemas de evaluación de los resultados de aprendizaje que desarrolla o implementa el programa, junto con las acciones emprendidas como resultado de dichas apreciaciones. | AK4: A54. Evidencia de la aplicación de una política Institucional que establezca parámetros para la formulación, evaluación y mejora continua de los resultados de aprendizaje establecidos en el programa, en alineación con el perfil de formación y acorde con el nivel y la modalidad de formación. | AL4: A56. Evidencia del resultado de la aplicación de estrategias para el desarrollo de las competencias previstas acordes con el perfil de formación del programa. | AM4: A57. Evidencia del cumplimiento de planes de mejoramiento y de innovación producto del proceso de autoevaluación del programa. | AN4: A59. Evidencia de la participación de los profesores y estudiantes en la proyección social del programa. | AO4: A61. Análisis del efecto de las políticas, estrategias y acciones orientadas al mejoramiento de la permanencia y la graduación en el programa, que incluyan el comportamiento en los últimos seis años o en la vigencia de la acreditación si se trata de una renovación, de la tasa de deserción interanual, tasa de deserción por cohorte y la tasa de graduación acumulada del programa. | AP4: A62. Evidencia de la existencia e implementación de un sistema de alertas tempranas que permita reconocer las particularidades de los estudiantes según su contexto sociocultural y la puesta en marcha de acciones que faciliten su proceso formativo, de acuerdo, al menos, con las normas nacionales vigentes en materia de inclusión y diversidad. | AQ4: A65. Evidencia de la evaluación y el mejoramiento de los aspectos curriculares derivados de los análisis del desempeño académico de los estudiantes, la permanencia y la graduación. | AR4: A66. Evidencia y análisis de la evolución de la matrícula total de estudiantes del programa y de la relación entre aspirantes inscritos, admitidos y matriculados en cada periodo, a fin de establecer la tasa de selectividad y/o absorción del programa. | AS4: A68. Evidencia del efecto de la aplicación de políticas y estrategias de cooperación con comunidades, nacionales e internacionales, en el desarrollo de labores formativas, académicas, docentes, científicas, culturales, deportivas y de extensión, así como en aspectos curriculares y en la revisión de tendencias y referentes nacionales e internacionales que contribuyan al mejoramiento continuo del programa. | AT4: A69. Evidencia y análisis de los resultados de la cooperación académica y científica del programa, mediante convenios, proyectos conjuntos, intercambios de profesores, estudiantes y la participación en redes científicas, culturales y de extensión. | AU4: A71. Evidencia de la incidencia de las estrategias empleadas para el desarrollo de las competencias comunicativas en una segunda lengua y las interacciones de profesores y estudiantes con otras comunidades no hispanohablantes de acuerdo con el nivel de formación y modalidad del programa. | AV4: A72. Evidencia de las estrategias implementadas para el desarrollo de las competencias investigativas, de innovación o creación artística y cultural de los estudiantes, en coherencia con la naturaleza, nivel de formación y la modalidad de oferta del programa. | AW4: A74. Evidencia de la existencia de un reglamento de propiedad intelectual, de grupos de investigación categorizados y de profesores investigadores reconocidos en las convocatorias de medición de Minciencias, acorde con el Proyecto Educativo del Programa, el nivel de formación y la modalidad del programa. | AX4: A76. Análisis sistemáticos de la participación de estudiantes y profesores en las actividades de bienestar en cada uno de los escenarios de práctica. | AY4: A78. Análisis sistemáticos de la participación de la comunidad del programa en los planes y las actividades de bienestar, de acuerdo con las particularidades de la población estudiantil, académica y administrativa. | AZ4: A80. Demostración de los resultados y la incidencia de la implementación de las estrategias y recursos de apoyo (pedagógico-didáctico) en los contextos de actuación de los profesores para el mejoramiento de sus prácticas de enseñanza-aprendizaje teniendo en cuenta la diversidad y la inclusión. | BA4: A83. Evidencia de la disponibilidad y capacidad de talleres, laboratorios, equipos, medios audiovisuales, sitios de práctica, estaciones y granjas experimentales, escenarios de simulación virtual, entre otros, para el adecuado desarrollo de la actividad docente, investigativa y de extensión, según requerimientos del programa. | BB4: A86. Análisis de la correspondencia entre la inversión en recursos bibliográficos y de información, su utilización por parte de la comunidad del programa, demostrando la suficiencia y pertinencia para el desarrollo de actividades de docencia, investigación y extensión, de acuerdo con el nivel de formación y modalidad del programa. | BC4: A88. Evidencia de la participación de representantes de la comunidad académica, a través de estructuras organizacionales definidas por la institución, y de su contribución, en el desarrollo y mejoramiento del programa. | BD4: A90. Evidencia de los mecanismos existentes para la dirección y gestión del programa que contribuyen al mejoramiento de las dinámicas administrativas y académicas y al relacionamiento con los grupos de interés. | BE4: A92. Presentación de estudios de satisfacción de profesores y estudiantes del programa acerca de la suficiencia y calidad de los recursos y sistemas de comunicación e información. | BF4: A95. Presentación de estadísticas y análisis de las capacidades Institucionales en materia de recursos humanos (planta docente y personal administrativo), técnicos, tecnológicos y financieros, que favorecen la permanencia, el desarrollo académico y la graduación de los estudiantes. | BG4: A97. Demostración de la consistencia entre la asignación y distribución presupuestal del programa, y el desarrollo de las actividades de docencia, investigación, creación artística y cultural, deportiva, proyección social, bienestar institucional e internacionalización, y la implementación de los planes de mejoramiento. | BH4: A99. Evidencia de la consolidación de un Sistema Interno de Aseguramiento de la Calidad que permita verificar, mediante unos procesos periódicos y participativos de autoevaluación, la alta calidad en cada uno de los factores y características del modelo del Consejo Nacional de Acreditación, en el programa. | BI4: A101. Demostración de la existencia de aulas, laboratorios, talleres, centros de simulación, plataformas tecnológicas, biblioteca y salas de estudio, para el cumplimiento de las labores formativas, académicas, docentes, científicas, culturales y de extensión, en coherencia con el nivel de formación y la modalidad de oferta del programa. | BJ4: A103. Evidencia de la coherencia entre los recursos informáticos y de comunicación con las necesidades para el desarrollo y cumplimiento de las labores formativas, académicas, docentes, científicas, culturales del programa en el lugar de desarrollo y en los escenarios de práctica. | BL4: Mejoramiento | BM4: DOCENCIA | BO4: OE1_Diseñar e implementar estrategias integrales e innovadoras para arraigar la identidad de UNICESMAG | BP4: Innovación en el Modelo Pedagógico | BQ4: Trazabilidad de los RA en el macro, meso y micro currículo | BR4: Transformación y apropiación de la gobernabilidad y gobernanza institucional, mediante un marco normativo actualizado y pertinente.
A5: F2. Estudiantes | C5: C2. Relevancia académica y pertinencia social del programa académico | D5: C4. Orientación y seguimiento a estudiantes | E5: C9. Estatuto profesoral | F5: C17. Impacto de los egresados en el medio social y académico | G5: C19. Flexibilidad de los aspectos curriculares. | H5: C28. Caracterización de estudiantes y sistema de alertas tempranas. | I5: C32. Relaciones externas de profesores y estudiantes | J5: C35. Compromiso con la investigación, desarrollo tecnológico, la innovación y la creación | K5: C37. Participación y seguimiento | L5: C39. Estrategias y recursos de apoyo a estudiantes | M5: C42. Dirección y gestión | N5: C48. Recursos informáticos y de comunicación. | P5: A3. Estudio de la pertinencia social del programa desde la perspectiva de la comunidad académica y de sus grupos de interés con el fin de identificar necesidades y requerimientos del entorno local, regional o nacional en términos productivos y de competitividad, tecnológicos, culturales, científicos y de talento humano. | Q5: A6. Resultados del análisis de la participación y principales logros de los estudiantes en actividades de investigación, desarrollo tecnológico, innovación, creación artística, culturales y deportivas. | T5: A12. Evidencia de los mecanismos para la aplicación, actualización y divulgación del reglamento estudiantil. | U5: A14. Apreciación de los estudiantes del programa frente a la aplicación de los estímulos académicos y apoyos socioeconómicos, y el cumplimiento institucional de estas medidas, junto con las acciones emprendidas como resultado de dichas apreciaciones. | V5: A16. Apreciación de los profesores sobre la aplicación, pertinencia y vigencia de las políticas, normas y criterios académicos establecidos por la institución para su selección, vinculación y permanencia, junto con las acciones emprendidas como resultado de dichas apreciaciones. | W5: A18. Resultados en el mejoramiento de la calidad del programa, a partir de la aplicación de un estatuto que promueve la trayectoria profesoral, la inclusión, el reconocimiento de los méritos y el ascenso en el escalafón. | X5: A21. Evidencia de la existencia de un núcleo básico de profesores de tiempo completo, preferiblemente con contratación a término indefinido, y su relación con la formación de la comunidad académica del programa y el cumplimiento con alta calidad de las funciones esenciales del programa. | Y5: A28. Evidencia de cómo el desarrollo profesoral atiende a la diversidad de los estudiantes, a las modalidades de la docencia y a los requerimientos de internacionalización y de inter y multiculturalidad de profesores y estudiantes. | Z5: A31. Apreciación de directivos y profesores del programa, sobre el efecto que ha tenido el régimen de estímulos al profesorado en el ejercicio cualificado de la docencia, la investigación, la innovación, la creación artística y cultural, la extensión o proyección social, en los aportes al desarrollo técnico y tecnológico y la cooperación internacional, junto con las acciones emprendidas como resultado de dichas apreciaciones. | AA5: A33. Presentación de los resultados de evaluación de los materiales académicos producidos por los profesores para el desarrollo de las diversas actividades académicas, que soportan los ambientes de aprendizaje, de acuerdo con el nivel de formación y modalidad. | AC5: A37. Demostración del mejoramiento continuo del programa, a partir de las evaluaciones permanentes realizadas a los profesores, en coherencia con el nivel de formación y modalidad. | AD5: A39. Apreciación de los egresados en relación con el perfil de formación, las competencias adquiridas y las posibilidades que les ha ofrecido su formación para su desarrollo profesional y laboral, junto con las acciones emprendidas como resultado de dichas apreciaciones. | AE5: A41. Apreciación de empleadores sobre el desempeño destacado de los egresados y su aporte en la solución de los problemas académicos, ambientales, tecnológicos, sociales y culturales, junto con las acciones emprendidas como resultado de dichas apreciaciones. | AF5: A43. Evaluación de las estrategias y acciones del programa para el mejoramiento de las competencias definidas por el programa. | AG5: A45. Apreciación de estudiantes, profesores y egresados sobre las rutas de formación alternativas y adoptadas por los estudiantes a partir de sus necesidades e intereses, derivadas de las estrategias de flexibilidad curricular definidas por la institución, junto con las acciones emprendidas como resultado de dichas apreciaciones. | AH5: A47. Apreciación de los estudiantes y profesores frente a los mecanismos y criterios dispuestos por la institución para la interdisciplinariedad curricular del programa, los resultados de su análisis y la evidencia de los logros en el mejoramiento en la calidad del programa. | AI5: A49. Evidencia de la evaluación y el mejoramiento de las estrategias y prácticas pedagógicas, a partir de los aportes de la investigación pedagógica y de los procesos de actualización de los profesores. | AJ5: A52. Evidencia de los resultados obtenidos a partir de la implementación de los sistemas de evaluación de estudiantes basado en políticas y normas claras, universales y transparentes. | AK5: A55. Evidencia del proceso de mejoramiento continuo relacionado con la evaluación entre los resultados de aprendizaje esperados y los alcanzados por los estudiantes, el sistema de evaluación de estudiantes y las acciones de ajuste de los aspectos curriculares y las metodologías de enseñanza - aprendizaje derivadas de dicha evaluación. | AM5: A58. Apreciación de los profesores y estudiantes sobre la calidad y pertinencia del proceso de evaluación y autorregulación del programa, junto con las acciones emprendidas como resultado de dichas apreciaciones. | AN5: A60. Evidencia del efecto de las estrategias y acciones de proyección social como un mecanismo para establecer los aportes del programa a la solución de problemas de la sociedad y a las mejoras de los aspectos curriculares. | AP5: A63. Apreciación de estudiantes y profesores sobre la contribución de las estrategias del sistema de alertas tempranas en su permanencia y graduación, junto con las acciones emprendidas como resultado de dichas apreciaciones. | AR5: A67. Análisis de la correlación entre los mecanismos de selección, de desempeño académico, permanencia y graduación que resulte en ajustes a los procesos de selección del programa. | AT5: A70. Apreciación de profesores, estudiantes y egresados sobre los resultados de la cooperación académica y científica derivados de la aplicación de políticas y estrategias que favorezcan la interacción de profesores y estudiantes con sus homólogos, a nivel nacional e internacional, junto con las acciones emprendidas como resultado de dichas apreciaciones. | AV5: A73. Apreciación de los estudiantes acerca de la formación para la investigación, el desarrollo de un pensamiento crítico, creativo e innovador, así como el desarrollo tecnológico, la innovación y la creación promovida en el programa, junto con las acciones emprendidas como resultado de dichas apreciaciones. | AW5: A75. Evidencia de resultados de investigación, desarrollo tecnológico, innovación o creación de los profesores del programa, que contribuyan al fortalecimiento de los aspectos curriculares, la formación de los estudiantes y a la generación de nuevo conocimiento o a la solución de problemas de la sociedad, en coherencia con el Proyecto Educativo del Programa, el nivel de formación y la modalidad del programa. | AX5: A77. Apreciación de los estudiantes, profesores y personal administrativo sobre la incidencia de la implementación de políticas, programas y servicios de bienestar, en coherencia con las condiciones y necesidades de la comunidad en cada uno de los lugares y escenarios de práctica donde desarrolla sus labores, en correspondencia con el nivel de formación y la modalidad del programa, junto con las acciones emprendidas como resultado de dichas apreciaciones. | AY5: A79. Evaluación de la calidad y pertinencia de la infraestructura, espacios y servicios de bienestar por parte de la comunidad del programa, junto con las acciones emprendidas como resultado de dicha evaluación. | AZ5: A81. Apreciación de los profesores y los estudiantes en relación con las estrategias pedagógicas, tecnológicas y de acompañamiento dispuestas por el programa para el desarrollo de las habilidades comunicativas y de interacción de los profesores con los estudiantes, junto con las acciones emprendidas como resultado de dichas apreciaciones. | BA5: A84. Apreciación de los estudiantes sobre la utilidad y pertinencia de las estrategias y recursos de apoyo brindados por la institución para el desarrollo de su proceso formativo en diferentes contextos, junto con las acciones emprendidas como resultado de dichas apreciaciones. | BB5: A87. Apreciación de estudiantes y profesores acerca de la pertinencia, actualización y suficiencia del material bibliográfico con que cuenta el programa, para apoyar el desarrollo de las distintas actividades académicas, de acuerdo con su nivel de formación y modalidad, junto con las acciones emprendidas como resultado de dichas apreciaciones. | BC5: A89. Apreciación de estudiantes, profesores y egresados sobre su participación en cuerpos colegiados, y en decisiones orientadas al mejoramiento del programa, junto con las acciones emprendidas como resultado de dichas apreciaciones. | BD5: A91. Apreciación de profesores y estudiantes sobre la eficiencia, eficacia y orientación de los procesos administrativos hacia el desarrollo de las labores formativas, académicas, docentes, científicas, culturales y de extensión, junto con las acciones emprendidas como resultado de dichas apreciaciones. | BE5: A93. Presentación de estadísticas y análisis del uso de los sistemas de comunicación e información, y de la implementación de estrategias que garanticen la conectividad a los miembros de la comunidad académica del programa. | BF5: A96. Apreciación de profesores y estudiantes del programa con respecto a la correspondencia entre las capacidades Institucionales en materia de sus recursos humanos, técnicos, tecnológicos y financieros, y el número de estudiantes matriculados, en cumplimiento del Proyecto Educativo del Programa, junto con las acciones emprendidas como resultado de dichas apreciaciones. | BG5: A98. Presentación de la proyección y la ejecución del presupuesto de inversión y de funcionamiento del programa y los mecanismos de seguimiento y control. | BH5: A100. En el caso de los programas académicos del área de la salud, evidencia de los procesos de autoevaluación sobre el funcionamiento del convenio docencia servicio en cada uno de los escenarios de práctica y su incidencia en los procesos de mejoramiento. | BI5: A102. Evidencia de planes y proyectos realizados o en ejecución, para la conservación, expansión, mejoras y mantenimiento de la planta física para el programa, de acuerdo con las normas técnicas respectivas y con el nivel de formación y la modalidad de oferta del programa. | BJ5: A104. Apreciación de directivos, profesores y estudiantes del programa sobre la pertinencia, correspondencia y suficiencia de los recursos informáticos y de comunicación con que cuenta el programa. | BL5: Fortalecimiento | BM5: INVESTIGACIÓN Y EXTENSIÓN | BO5: OE2_Articular las labores institucionales desde una óptica transformadora de la persona para impactar la sociedad desde el reconocimiento de las culturas y las comunidades | BP5: Apropiación de la identidad institucional | BQ5: Interacción social pertinente | BR5: Consolidación de la comunidad UNICESMAG, a través de una arquitectura institucional eficiente.
A6: F3. Profesores | D6: C5. Capacidad de trabajo autónomo | E6: C10. Número, dedicación, nivel de formación y experiencia | G6: C20. Interdisciplinariedad | H6: C29. Ajustes a los aspectos curriculares | I6: C33. Habilidades comunicativas en una segunda lengua | L6: C40. Recursos bibliográficos y de información | M6: C43. Sistemas de comunicación e información | P6: A4. Evidencia de las transformaciones sociales pertinentes para el contexto y el territorio en el que se ofrece el programa académico, y del entorno tanto nacional como internacional. | Q6: A7. Resultados del análisis de la participación y principales logros de los estudiantes en proyectos de desarrollo empresarial, relacionamiento nacional e internacional. | W6: A19. Apreciación de los profesores sobre la aplicación y pertinencia del estatuto profesoral y de las políticas que establecen distinciones, estímulos que promueven la trayectoria profesoral, junto con las acciones emprendidas como resultado de dichas apreciaciones. | X6: A22. Evidencia de la vinculación de una planta profesoral pertinente con el área disciplinar del programa (TyT) con título de especialista y experiencia pedagógica y profesional certificada en los campos de formación del programa, que garantice del logro de los resultados de aprendizaje de los estudiantes y el cumplimiento de las funciones asignadas en condiciones de calidad, atendiendo a estándares internacionales, en coherencia con el nivel de formación y modalidad del programa. | Y6: A29. Apreciación de directivos y profesores del programa sobre los resultados que han tenido las acciones orientadas al desarrollo integral de los profesores, en el mejoramiento de las competencias pedagógicas, científicas y sociales para el sostenimiento de las funciones misionales, junto con las acciones emprendidas como resultado de dichas apreciaciones. | AA6: A34. Apreciación de los estudiantes y directivos del programa sobre la pertinencia y calidad del material académico producido, de acuerdo con el nivel de formación y la modalidad del programa, junto con las acciones emprendidas como resultado de dichas apreciaciones. | AI6: A50. En el caso de programas académicos del área de la salud, presentar análisis de la incidencia de las actividades desarrolladas en el marco de los convenios de docencia servicio con los distintos escenarios de práctica (con énfasis en el escenario principal, cuando aplique) en los procesos de formación. Los análisis se deben realizar entre las partes que participan en el convenio. | AJ6: A53. Evidencia de sistemas de evaluación que integran la innovación para generar transformaciones profundas en el Aprendizaje, y que acogen dinámicas en referencia a cambios en el conocimiento. | AP6: A64. Presentación del análisis de los resultados derivados del sistema de alertas tempranas y su impacto en el currículo, para mejorar el desempeño académico de los estudiantes, su permanencia y graduación. | AZ6: A82. En el caso de programas académicos del área de la salud, análisis de las acciones que realizan conjuntamente el programa con los escenarios de práctica, en sus procesos de certificación, acreditación, reconocimiento como hospital universitario y acciones de mejora. | BA6: A85. En el caso de los programas académicos del área de la salud, evidencia de la disponibilidad de laboratorios especializados y/o de simulación en los distintos lugares de desarrollo y los escenarios de práctica, y análisis del nivel de uso por parte de profesores y estudiantes. | BE6: A94. Evidencia de la aplicación de mecanismos de gestión documental, organización, actualización y seguridad de los registros y archivos académicos de estudiantes, profesores, personal directivo y administrativo. | BM6: DIRECCIONAMIENTO ESTRATÉGICO | BO6: OE3_Desarrollar una arquitectura institucional bajo los principios de ética y buen gobierno | BP6: Fomento de la cultura de autoevaluación al quehacer institucional | BQ6: Sostenibilidad administrativa y financiera. | BR6: Toma de decisiones con base en información confiable
A7: F4. Egresados | D7: C6. Reglamento estudiantil y política académica | E7: C11. Desarrollo profesoral | G7: C21. Estrategias pedagógicas. | H7: C30. Mecanismos de selección | M7: C44. Estudiantes y capacidad institucional | Q7: A8. Resultados del análisis de la participación y principales logros de los estudiantes en otras acciones de formación complementaria, que promuevan la comprensión de la realidad social, la empatía, la ética, habilidades blandas, así como el relacionamiento con otras culturas y lenguas, de acuerdo con el nivel de formación y la modalidad del programa. | X7: A23. Evidencia de la vinculación de una planta profesoral pertinente con el área disciplinar del programa (Prof) con título de especialistas, magísteres y/o doctores con experiencia o formación pedagógica y profesional certificada, que garantice el logro de los resultados de aprendizaje de los estudiantes y el cumplimiento de las funciones asignadas en condiciones de calidad, atendiendo a estándares internacionales, en coherencia con el nivel de formación y modalidad del programa. | BM7: ASEGURAMIENTO Y GESTIÓN DE LA CALIDAD | BP7: Innovación en los procesos de bienestar, permanencia, inclusión y graduación | BQ7: Creación de entornos tecnológicos sostenibles para las labores formativas
A8: F5. Aspectos académicos y resultados de aprendizaje | D8: C7. Estímulos y apoyos para estudiantes | E8: C12. Estímulos a la trayectoria profesoral | G8: C22. Sistema de evaluación de estudiantes | M8: C45. Financiación del programa académico | X8: A24. Evidencia de la vinculación de una planta profesoral pertinente con el área disciplinar del programa (Esp) con título de medicina y especialidad médico-quirúrgica, con experiencia o formación pedagógica y profesional certificada en el campo de práctica de la especialidad, que garantice el logro de los resultados de aprendizaje de los estudiantes y el cumplimiento de las funciones asignadas en condiciones de calidad, atendiendo a estándares internacionales, en coherencia con el nivel de formación y modalidad del programa. | BM8: GESTIÓN JURÍDICA | BQ8: Interinstitucionalización de la UNICESMAG
A9: F6. Permanencia y graduación | E9: C13. Producción, pertinencia, utilización e impacto de material docente | G9: C23. Resultados de aprendizaje | M9: C46. Aseguramiento de la alta calidad y mejora continua | X9: A25. Evidencia de la vinculación de una planta profesoral pertinente con el área disciplinar del programa (Mg) con título de maestría y/o doctorado con experiencia o formación pedagógica, investigativa y profesional certificada y experiencia en investigación, que garantice el logro de los resultados de aprendizaje de los estudiantes y el cumplimiento de las funciones asignadas en condiciones de calidad, atendiendo a estándares internacionales, en coherencia con el nivel de formación y modalidad del programa. | BM9: GESTIÓN HUMANA | BQ9: Fortalecimiento de la investigación, innovación y/o creación artística y cultural
A10: F7. Interacción con el entorno nacional e internacional | E10: C14. Remuneración por méritos | G10: C24. Competencias | X10: A26. Evidencia de la vinculación de una planta profesoral pertinente con el área disciplinar del programa (Dr) con título de doctorado y con experiencia en la dirección de tesis doctorales, así como publicaciones en revistas indexadas y libros en los campos de conocimiento, reconocidos en el Ministerio de Ciencia, Tecnología e Innovación (Minciencias), con experiencia o formación pedagógica, que garantice el logro de los resultados de aprendizaje de los estudiantes y el cumplimiento de las funciones asignadas en condiciones de calidad, atendiendo a estándares internacionales, en coherencia con el nivel de formación y modalidad del programa. | BM10: GESTIÓN DEL BIENESTAR INSTITUCIONAL
A11: F8. Aportes de la investigación, la innovación, el desarrollo tecnológico y la creación, asociados al programa académico | E11: C15. Evaluación de profesores | G11: C25. Evaluación y autorregulación del programa académico | BM11: GESTIÓN DE LA COMUNICACIÓN
A12: F9. Bienestar de la comunidad académica del programa | G12: C26. Vinculación e interacción social | BM12: GESTIÓN DE LA EVANGELIZACIÓN
A13: F10. Medios educativos y ambientes de aprendizaje | BM13: GESTIÓN DE LA TECNOLOGÍA
A14: F11. Organización, administración y financiación del programa académico | BM14: GESTIÓN DE BIENES Y SERVICIOS
A15: F12. Recursos físicos y tecnológicos | BM15: GESTIÓN FINANCIERA
BM16: GESTIÓN DOCUMENTAL

Sheet PM
D2: UNIVERSIDAD CESMAG
D4: PLAN DE MEJORAMIENTO | I4: INSTRUCCIONES: 1. No alterar la estructura del formato. 2. No combinar celdas horizontal o verticalmente, en caso que se requiera asociar varios indicadores a una actividad se debe repetir su postulado en las filas que sea necesario. 3. Utilizar las listas de selección en los campos cuyo encabezado está resaltado con fondo rojo. 4. Diligenciar completamente los campos para cada actividad de mejoramiento o fortalecimiento identificadas.
D5: AÑO: | E5: 2027 - 2029
D7: PROGRAMA:
B10: CÓDIGO OBJETIVO | C10: FACTOR | D10: CARACTERÍSTICA | E10: ASPECTO / HALLAZGO | F10: CALIFICACIÓN | G10: TIPO DE ACCIÓN | H10: OBJETIVO | I10: NOMBRE DE LA ACTIVIDAD | J10: DESCRIPCIÓN DE LA ACTIVIDAD | K10: INDICADOR | L10: META | M10: FECHA INICIO | N10: FECHA FIN | O10: RECURSOS | P10: VALOR PRESUPUESTO | Q10: PROCESO RESPONSABLE | R10: CARGO RESPONSABLE | S10: ALCANCE | T10: EJE ESTRATÉGICO | U10: OBJETIVO ESTRATÉGICO | V10: PROYECTO PDI
B11: OPM_01 | C11: F4. Egresados | D11: C17. Impacto de los egresados en el medio social y académico | H11: Desarrollar un estudio cualitativo y cuantitativo del contexto, para establecer propuestas de solución a las necesidades encontradas en el plan de estudios | I11: Estudio de las necesidades del contexto regional en el marco de la política pública nacional y regional. | J11: Se adelantará un estudiocualitativo y cuantitativo para reconocer las necesidades del contexto a nivel regional y nacional. El estudio del resultado para establecer propuestas de modificación del plan de estudios | K11: Documento estudio del contexto | L11: 1 | O11: Recursos humanos, tecnológicos y financieros | P11: =SUMIF(PERSONAL!H:H,PM!B11,PERSONAL!G:G)+SUMIF('ADQUISICIÓN DE ACTIVOS'!H:H,PM!B11,'ADQUISICIÓN DE ACTIVOS'!G:G)+SUMIF(PUBLICIDAD!H:H,PM!B11,PUBLICIDAD!G:G)+SUMIF('ÚTILES Y PAPELERÍA'!H:H,PM!B11,'ÚTILES Y PAPELERÍA'!G:G)+SUMIF('ESPACIOS FÍSICOS y EQUIP'!I:I,PM!B11,'ESPACIOS FÍSICOS y EQUIP'!H:H)+SUMIF(DIVERSOS!H:H,PM!B11,DIVERSOS!G:G) -> 18731250 | Q11: DOCENCIA | R11: Dirección Programa de Psicología | S11: PROGRAMA | U11: Ofrecer_programas_de_calidad | V11: Actualización de los PEP en coherencia con el PEI, Misión y Visión Institucionales y carácter institucional.
B12: OPM_02 | H12: Presentar propuestas que permitan realizar cambios en el plan de estudios en articulación con la renovación de registro calificado. | I12: Análisis del plan de estudios del Programa de Psicología | J12: A partir del estudio y las conclusiones del estudio de necesidades se presentarán propuestas para el plan de estudios ofertado por el Programa de Psicología. | K12: Documento propuestas para cambios en el plan de estudios | L12: 1 | O12: Recursos humanos, tecnológicos y financieros | P12: =SUMIF(PERSONAL!H:H,PM!B12,PERSONAL!G:G)+SUMIF('ADQUISICIÓN DE ACTIVOS'!H:H,PM!B12,'ADQUISICIÓN DE ACTIVOS'!G:G)+SUMIF(PUBLICIDAD!H:H,PM!B12,PUBLICIDAD!G:G)+SUMIF('ÚTILES Y PAPELERÍA'!H:H,PM!B12,'ÚTILES Y PAPELERÍA'!G:G)+SUMIF('ESPACIOS FÍSICOS y EQUIP'!I:I,PM!B12,'ESPACIOS FÍSICOS y EQUIP'!H:H)+SUMIF(DIVERSOS!H:H,PM!B12,DIVERSOS!G:G) -> 4052170.6 | Q12: DOCENCIA | R12: Dirección Programa de Psicología | S12: PROGRAMA
B13: OPM_03 | H13: Diseñar una estrategia para el seguimiento a los proyectos que adelanta el programa, mediante sus funciones de docencia, investigación, innovación, creación artística y cultural, y extensión. | I13: Estrategia de seguimiento a proyectos adelantados por el programa | J13: Identificación y sistematización de los proyectos que adelanta el programa, mediante sus funciones de docencia, investigación, innovación, creación artística y cultural, y extensión. | K13: Documento de la estrategia de seguimiento a proyectos adelantados por el programa | L13: 1 | O13: Recursos humanos, tecnológicos y financieros | P13: =SUMIF(PERSONAL!H:H,PM!B13,PERSONAL!G:G)+SUMIF('ADQUISICIÓN DE ACTIVOS'!H:H,PM!B13,'ADQUISICIÓN DE ACTIVOS'!G:G)+SUMIF(PUBLICIDAD!H:H,PM!B13,PUBLICIDAD!G:G)+SUMIF('ÚTILES Y PAPELERÍA'!H:H,PM!B13,'ÚTILES Y PAPELERÍA'!G:G)+SUMIF('ESPACIOS FÍSICOS y EQUIP'!I:I,PM!B13,'ESPACIOS FÍSICOS y EQUIP'!H:H)+SUMIF(DIVERSOS!H:H,PM!B13,DIVERSOS!G:G) -> 0 | Q13: DOCENCIA | R13: Dirección Programa de Psicología | S13: PROGRAMA
B14: OPM_04 | P14: =SUMIF(PERSONAL!H:H,PM!B14,PERSONAL!G:G)+SUMIF('ADQUISICIÓN DE ACTIVOS'!H:H,PM!B14,'ADQUISICIÓN DE ACTIVOS'!G:G)+SUMIF(PUBLICIDAD!H:H,PM!B14,PUBLICIDAD!G:G)+SUMIF('ÚTILES Y PAPELERÍA'!H:H,PM!B14,'ÚTILES Y PAPELERÍA'!G:G)+SUMIF('ESPACIOS FÍSICOS y EQUIP'!I:I,PM!B14,'ESPACIOS FÍSICOS y EQUIP'!H:H)+SUMIF(DIVERSOS!H:H,PM!B14,DIVERSOS!G:G) -> 0
B15: OPM_05 | P15: =SUMIF(PERSONAL!H:H,PM!B15,PERSONAL!G:G)+SUMIF('ADQUISICIÓN DE ACTIVOS'!H:H,PM!B15,'ADQUISICIÓN DE ACTIVOS'!G:G)+SUMIF(PUBLICIDAD!H:H,PM!B15,PUBLICIDAD!G:G)+SUMIF('ÚTILES Y PAPELERÍA'!H:H,PM!B15,'ÚTILES Y PAPELERÍA'!G:G)+SUMIF('ESPACIOS FÍSICOS y EQUIP'!I:I,PM!B15,'ESPACIOS FÍSICOS y EQUIP'!H:H)+SUMIF(DIVERSOS!H:H,PM!B15,DIVERSOS!G:G) -> 0
B16: OPM_06 | P16: =SUMIF(PERSONAL!H:H,PM!B16,PERSONAL!G:G)+SUMIF('ADQUISICIÓN DE ACTIVOS'!H:H,PM!B16,'ADQUISICIÓN DE ACTIVOS'!G:G)+SUMIF(PUBLICIDAD!H:H,PM!B16,PUBLICIDAD!G:G)+SUMIF('ÚTILES Y PAPELERÍA'!H:H,PM!B16,'ÚTILES Y PAPELERÍA'!G:G)+SUMIF('ESPACIOS FÍSICOS y EQUIP'!I:I,PM!B16,'ESPACIOS FÍSICOS y EQUIP'!H:H)+SUMIF(DIVERSOS!H:H,PM!B16,DIVERSOS!G:G) -> 0
B17: OPM_07 | P17: =SUMIF(PERSONAL!H:H,PM!B17,PERSONAL!G:G)+SUMIF('ADQUISICIÓN DE ACTIVOS'!H:H,PM!B17,'ADQUISICIÓN DE ACTIVOS'!G:G)+SUMIF(PUBLICIDAD!H:H,PM!B17,PUBLICIDAD!G:G)+SUMIF('ÚTILES Y PAPELERÍA'!H:H,PM!B17,'ÚTILES Y PAPELERÍA'!G:G)+SUMIF('ESPACIOS FÍSICOS y EQUIP'!I:I,PM!B17,'ESPACIOS FÍSICOS y EQUIP'!H:H)+SUMIF(DIVERSOS!H:H,PM!B17,DIVERSOS!G:G) -> 0
B18: OPM_08 | P18: =SUMIF(PERSONAL!H:H,PM!B18,PERSONAL!G:G)+SUMIF('ADQUISICIÓN DE ACTIVOS'!H:H,PM!B18,'ADQUISICIÓN DE ACTIVOS'!G:G)+SUMIF(PUBLICIDAD!H:H,PM!B18,PUBLICIDAD!G:G)+SUMIF('ÚTILES Y PAPELERÍA'!H:H,PM!B18,'ÚTILES Y PAPELERÍA'!G:G)+SUMIF('ESPACIOS FÍSICOS y EQUIP'!I:I,PM!B18,'ESPACIOS FÍSICOS y EQUIP'!H:H)+SUMIF(DIVERSOS!H:H,PM!B18,DIVERSOS!G:G) -> 0
B19: OPM_09 | P19: =SUMIF(PERSONAL!H:H,PM!B19,PERSONAL!G:G)+SUMIF('ADQUISICIÓN DE ACTIVOS'!H:H,PM!B19,'ADQUISICIÓN DE ACTIVOS'!G:G)+SUMIF(PUBLICIDAD!H:H,PM!B19,PUBLICIDAD!G:G)+SUMIF('ÚTILES Y PAPELERÍA'!H:H,PM!B19,'ÚTILES Y PAPELERÍA'!G:G)+SUMIF('ESPACIOS FÍSICOS y EQUIP'!I:I,PM!B19,'ESPACIOS FÍSICOS y EQUIP'!H:H)+SUMIF(DIVERSOS!H:H,PM!B19,DIVERSOS!G:G) -> 0
B20: OPM_10 | P20: =SUMIF(PERSONAL!H:H,PM!B20,PERSONAL!G:G)+SUMIF('ADQUISICIÓN DE ACTIVOS'!H:H,PM!B20,'ADQUISICIÓN DE ACTIVOS'!G:G)+SUMIF(PUBLICIDAD!H:H,PM!B20,PUBLICIDAD!G:G)+SUMIF('ÚTILES Y PAPELERÍA'!H:H,PM!B20,'ÚTILES Y PAPELERÍA'!G:G)+SUMIF('ESPACIOS FÍSICOS y EQUIP'!I:I,PM!B20,'ESPACIOS FÍSICOS y EQUIP'!H:H)+SUMIF(DIVERSOS!H:H,PM!B20,DIVERSOS!G:G) -> 0
P21: =SUMIF(PERSONAL!H:H,PM!B21,PERSONAL!G:G)+SUMIF('ADQUISICIÓN DE ACTIVOS'!H:H,PM!B21,'ADQUISICIÓN DE ACTIVOS'!G:G)+SUMIF(PUBLICIDAD!H:H,PM!B21,PUBLICIDAD!G:G)+SUMIF('ÚTILES Y PAPELERÍA'!H:H,PM!B21,'ÚTILES Y PAPELERÍA'!G:G)+SUMIF('ESPACIOS FÍSICOS y EQUIP'!I:I,PM!B21,'ESPACIOS FÍSICOS y EQUIP'!H:H)+SUMIF(DIVERSOS!H:H,PM!B21,DIVERSOS!G:G) -> 0
P22: =SUMIF(PERSONAL!H:H,PM!B22,PERSONAL!G:G)+SUMIF('ADQUISICIÓN DE ACTIVOS'!H:H,PM!B22,'ADQUISICIÓN DE ACTIVOS'!G:G)+SUMIF(PUBLICIDAD!H:H,PM!B22,PUBLICIDAD!G:G)+SUMIF('ÚTILES Y PAPELERÍA'!H:H,PM!B22,'ÚTILES Y PAPELERÍA'!G:G)+SUMIF('ESPACIOS FÍSICOS y EQUIP'!I:I,PM!B22,'ESPACIOS FÍSICOS y EQUIP'!H:H)+SUMIF(DIVERSOS!H:H,PM!B22,DIVERSOS!G:G) -> 0
P23: =SUMIF(PERSONAL!H:H,PM!B23,PERSONAL!G:G)+SUMIF('ADQUISICIÓN DE ACTIVOS'!H:H,PM!B23,'ADQUISICIÓN DE ACTIVOS'!G:G)+SUMIF(PUBLICIDAD!H:H,PM!B23,PUBLICIDAD!G:G)+SUMIF('ÚTILES Y PAPELERÍA'!H:H,PM!B23,'ÚTILES Y PAPELERÍA'!G:G)+SUMIF('ESPACIOS FÍSICOS y EQUIP'!I:I,PM!B23,'ESPACIOS FÍSICOS y EQUIP'!H:H)+SUMIF(DIVERSOS!H:H,PM!B23,DIVERSOS!G:G) -> 0
P24: =SUMIF(PERSONAL!H:H,PM!B24,PERSONAL!G:G)+SUMIF('ADQUISICIÓN DE ACTIVOS'!H:H,PM!B24,'ADQUISICIÓN DE ACTIVOS'!G:G)+SUMIF(PUBLICIDAD!H:H,PM!B24,PUBLICIDAD!G:G)+SUMIF('ÚTILES Y PAPELERÍA'!H:H,PM!B24,'ÚTILES Y PAPELERÍA'!G:G)+SUMIF('ESPACIOS FÍSICOS y EQUIP'!I:I,PM!B24,'ESPACIOS FÍSICOS y EQUIP'!H:H)+SUMIF(DIVERSOS!H:H,PM!B24,DIVERSOS!G:G) -> 0
P25: =SUMIF(PERSONAL!H:H,PM!B25,PERSONAL!G:G)+SUMIF('ADQUISICIÓN DE ACTIVOS'!H:H,PM!B25,'ADQUISICIÓN DE ACTIVOS'!G:G)+SUMIF(PUBLICIDAD!H:H,PM!B25,PUBLICIDAD!G:G)+SUMIF('ÚTILES Y PAPELERÍA'!H:H,PM!B25,'ÚTILES Y PAPELERÍA'!G:G)+SUMIF('ESPACIOS FÍSICOS y EQUIP'!I:I,PM!B25,'ESPACIOS FÍSICOS y EQUIP'!H:H)+SUMIF(DIVERSOS!H:H,PM!B25,DIVERSOS!G:G) -> 0
P26: =SUMIF(PERSONAL!H:H,PM!B26,PERSONAL!G:G)+SUMIF('ADQUISICIÓN DE ACTIVOS'!H:H,PM!B26,'ADQUISICIÓN DE ACTIVOS'!G:G)+SUMIF(PUBLICIDAD!H:H,PM!B26,PUBLICIDAD!G:G)+SUMIF('ÚTILES Y PAPELERÍA'!H:H,PM!B26,'ÚTILES Y PAPELERÍA'!G:G)+SUMIF('ESPACIOS FÍSICOS y EQUIP'!I:I,PM!B26,'ESPACIOS FÍSICOS y EQUIP'!H:H)+SUMIF(DIVERSOS!H:H,PM!B26,DIVERSOS!G:G) -> 0
P27: =SUMIF(PERSONAL!H:H,PM!B27,PERSONAL!G:G)+SUMIF('ADQUISICIÓN DE ACTIVOS'!H:H,PM!B27,'ADQUISICIÓN DE ACTIVOS'!G:G)+SUMIF(PUBLICIDAD!H:H,PM!B27,PUBLICIDAD!G:G)+SUMIF('ÚTILES Y PAPELERÍA'!H:H,PM!B27,'ÚTILES Y PAPELERÍA'!G:G)+SUMIF('ESPACIOS FÍSICOS y EQUIP'!I:I,PM!B27,'ESPACIOS FÍSICOS y EQUIP'!H:H)+SUMIF(DIVERSOS!H:H,PM!B27,DIVERSOS!G:G) -> 0
P28: =SUMIF(PERSONAL!H:H,PM!B28,PERSONAL!G:G)+SUMIF('ADQUISICIÓN DE ACTIVOS'!H:H,PM!B28,'ADQUISICIÓN DE ACTIVOS'!G:G)+SUMIF(PUBLICIDAD!H:H,PM!B28,PUBLICIDAD!G:G)+SUMIF('ÚTILES Y PAPELERÍA'!H:H,PM!B28,'ÚTILES Y PAPELERÍA'!G:G)+SUMIF('ESPACIOS FÍSICOS y EQUIP'!I:I,PM!B28,'ESPACIOS FÍSICOS y EQUIP'!H:H)+SUMIF(DIVERSOS!H:H,PM!B28,DIVERSOS!G:G) -> 0
P29: =SUMIF(PERSONAL!H:H,PM!B29,PERSONAL!G:G)+SUMIF('ADQUISICIÓN DE ACTIVOS'!H:H,PM!B29,'ADQUISICIÓN DE ACTIVOS'!G:G)+SUMIF(PUBLICIDAD!H:H,PM!B29,PUBLICIDAD!G:G)+SUMIF('ÚTILES Y PAPELERÍA'!H:H,PM!B29,'ÚTILES Y PAPELERÍA'!G:G)+SUMIF('ESPACIOS FÍSICOS y EQUIP'!I:I,PM!B29,'ESPACIOS FÍSICOS y EQUIP'!H:H)+SUMIF(DIVERSOS!H:H,PM!B29,DIVERSOS!G:G) -> 0

Sheet Hoja2
A1: FACTORES | B1: F1. Proyecto Educativo del Programa e Identidad Institucional | C1: F2. Estudiantes | D1: F3. Profesores | E1: F4. Egresados | F1: F5. Aspectos académicos y resultados de aprendizaje | G1: F6. Permanencia y graduación | H1: F7. Interacción con el entorno nacional e internacional | I1: F8. Aportes de la investigación, la innovación, el desarrollo tecnológico y la creación, asociados al programa académico | J1: F9. Bienestar de la comunidad académica del programa | K1: F10. Medios educativos y ambientes de aprendizaje | L1: F11. Organización, administración y financiación del programa académico | M1: F12. Recursos físicos y tecnológicos | O1: PROCESO RESPONSABLE
A2: F1. Proyecto Educativo del Programa e Identidad Institucional | B2: C1. Proyecto Educativo del Programa | C2: C3. Participación en actividades de formación integral | D2: C8. Selección, vinculación y permanencia | E2: C16. Seguimiento de los egresados | F2: C18. Integralidad de los aspectos curriculares | G2: C27. Políticas, estrategias y estructura para la permanencia y la graduación | H2: C31. Inserción del programa en contextos académicos nacionales e internacionales | I2: C34. Formación para la investigación, desarrollo tecnológico, la innovación y la creación | J2: C36. Programas y servicios | K2: C38. Estrategias y recursos de apoyo a profesores | L2: C41. Organización y administración | M2: C47. Recursos de infraestructura física y tecnológica. | O2: DOCENCIA
A3: F2. Estudiantes | B3: C2. Relevancia académica y pertinencia social del programa académico | C3: C4. Orientación y seguimiento a estudiantes | D3: C9. Estatuto profesoral | E3: C17. Impacto de los egresados en el medio social y académico | F3: C19. Flexibilidad de los aspectos curriculares. | G3: C28. Caracterización de estudiantes y sistema de alertas tempranas. | H3: C32. Relaciones externas de profesores y estudiantes | I3: C35. Compromiso con la investigación, desarrollo tecnológico, la innovación y la creación | J3: C37. Participación y seguimiento | K3: C39. Estrategias y recursos de apoyo a estudiantes | L3: C42. Dirección y gestión | M3: C48. Recursos informáticos y de comunicación. | O3: INVESTIGACIÓN Y EXTENSIÓN
A4: F3. Profesores | C4: C5. Capacidad de trabajo autónomo | D4: C10. Número, dedicación, nivel de formación y experiencia | F4: C20. Interdisciplinariedad | G4: C29. Ajustes a los aspectos curriculares | H4: C33. Habilidades comunicativas en una segunda lengua | K4: C40. Recursos bibliográficos y de información | L4: C43. Sistemas de comunicación e información | O4: DIRECCIONAMIENTO ESTRATÉGICO
A5: F4. Egresados | C5: C6. Reglamento estudiantil y política académica | D5: C11. Desarrollo profesoral | F5: C21. Estrategias pedagógicas. | G5: C30. Mecanismos de selección | L5: C44. Estudiantes y capacidad institucional | O5: ASEGURAMIENTO Y GESTIÓN DE LA CALIDAD
A6: F5. Aspectos académicos y resultados de aprendizaje | C6: C7. Estímulos y apoyos para estudiantes | D6: C12. Estímulos a la trayectoria profesoral | F6: C22. Sistema de evaluación de estudiantes | L6: C45. Financiación del programa académico | O6: GESTIÓN JURÍDICA
A7: F6. Permanencia y graduación | D7: C13. Producción, pertinencia, utilización e impacto de material docente | F7: C23. Resultados de aprendizaje | L7: C46. Aseguramiento de la alta calidad y mejora continua | O7: GESTIÓN HUMANA
A8: F7. Interacción con el entorno nacional e internacional | D8: C14. Remuneración por méritos | F8: C24. Competencias | O8: GESTIÓN DEL BIENESTAR INSTITUCIONAL
A9: F8. Aportes de la investigación, la innovación, el desarrollo tecnológico y la creación, asociados al programa académico | D9: C15. Evaluación de profesores | F9: C25. Evaluación y autorregulación del programa académico | O9: GESTIÓN DE LA COMUNICACIÓN
A10: F9. Bienestar de la comunidad académica del programa | F10: C26. Vinculación e interacción social | O10: GESTIÓN DE LA EVANGELIZACIÓN
A11: F10. Medios educativos y ambientes de aprendizaje | O11: GESTIÓN DE LA TECNOLOGÍA
A12: F11. Organización, administración y financiación del programa académico | O12: GESTIÓN DE BIENES Y SERVICIOS
A13: F12. Recursos físicos y tecnológicos | O13: GESTIÓN FINANCIERA
O14: GESTIÓN DOCUMENTAL
M19: ALCANCE
B20: F1. Proyecto Educativo del Programa e Identidad Institucional | M20: INSTITUCIONAL
B21: F2. Estudiantes | M21: PROGRAMA
B22: F3. Profesores
B23: F4. Egresados
B24: F5. Aspectos académicos y resultados de aprendizaje
B25: F6. Permanencia y graduación
B26: F7. Interacción con el entorno nacional e internacional
B27: F8. Aportes de la investigación, la innovación, el desarrollo tecnológico y la creación, asociados al programa académico
B28: F9. Bienestar de la comunidad académica del programa
B29: F10. Medios educativos y ambientes de aprendizaje
B30: F11. Organización, administración y financiación del programa académico
B31: F12. Recursos físicos y tecnológicos
B34: TIPO DE ACCIÓN
B35: MEJORAMIENTO
B36: FORTALECIMIENTO
A39: EJES | F39: OBJETIVO ESTRATÉGICO | G39: OE1_Diseñar e implementar estrategias integrales e innovadoras para arraigar la identidad de UNICESMAG | H39: OE2_Articular las labores institucionales desde una óptica transformadora de la persona para impactar la sociedad desde el reconocimiento de las culturas y las comunidades | I39: OE3_Desarrollar una arquitectura institucional bajo los principios de ética y buen gobierno
A40: DOCENCIA | F40: OE1_Diseñar e implementar estrategias integrales e innovadoras para arraigar la identidad de UNICESMAG | G40: Innovación en el Modelo Pedagógico | H40: Trazabilidad de los RA en el macro, meso y micro currículo | I40: Transformación y apropiación de la gobernabilidad y gobernanza institucional, mediante un marco normativo actualizado y pertinente.
A41: INVESTIGACIÓN | F41: OE2_Articular las labores institucionales desde una óptica transformadora de la persona para impactar la sociedad desde el reconocimiento de las culturas y las comunidades | G41: Apropiación de la identidad institucional | H41: Interacción social pertinente | I41: Consolidación de la comunidad UNICESMAG, a través de una arquitectura institucional eficiente.
A42: EXTENSIÓN Y PROYECCIÓN SOCIAL | F42: OE3_Desarrollar una arquitectura institucional bajo los principios de ética y buen gobierno | G42: Fomento de la cultura de autoevaluación al quehacer institucional | H42: Sostenibilidad administrativa y financiera. | I42: Toma de decisiones con base en información confiable
A43: IDENTIDAD INSTITUCIONAL | G43: Innovación en los procesos de bienestar, permanencia, inclusión y graduación | H43: Creación de entornos tecnológicos sostenibles para las labores formativas
A44: BIENESTAR INSTITUCIONAL | H44: Interinstitucionalización de la UNICESMAG
A45: INFRAESTRUCTURA FÍSICA Y TECNOLÓGICA | H45: Fortalecimiento de la investigación, innovación y/o creación artística y cultural
A46: INTERNACIONALIZACIÓN
A47: GESTIÓN ORGANIZACIONAL Y ADMINISTRATIVA
A48: AUTOEVALUACIÓN Y ACREDITACIÓN
...

Sheet Hoja3
A1: C1. Proyecto Educativo del Programa | B1: C2. Relevancia académica y pertinencia social del programa académico | C1: C3. Participación en actividades de formación integral | D1: C4. Orientación y seguimiento a estudiantes | E1: C5. Capacidad de trabajo autónomo | F1: C6. Reglamento estudiantil y política académica | G1: C7. Estímulos y apoyos para estudiantes | H1: C8. Selección, vinculación y permanencia | I1: C9. Estatuto profesoral | J1: C10. Número, dedicación, nivel de formación y experiencia | K1: C11. Desarrollo profesoral | L1: C12. Estímulos a la trayectoria profesoral | M1: C13. Producción, pertinencia, utilización e impacto de material docente | N1: C14. Remuneración por méritos | O1: C15. Evaluación de profesores | P1: C16. Seguimiento de los egresados | Q1: C17. Impacto de los egresados en el medio social y académico | R1: C18. Integralidad de los aspectos curriculares | S1: C19. Flexibilidad de los aspectos curriculares. | T1: C20. Interdisciplinariedad | U1: C21. Estrategias pedagógicas. | V1: C22. Sistema de evaluación de estudiantes | W1: C23. Resultados de aprendizaje | X1: C24. Competencias | Y1: C25. Evaluación y autorregulación del programa académico | Z1: C26. Vinculación e interacción social | AA1: C27. Políticas, estrategias y estructura para la permanencia y la graduación | AB1: C28. Caracterización de estudiantes y sistema de alertas tempranas. | AC1: C29. Ajustes a los aspectos curriculares | AD1: C30. Mecanismos de selección | AE1: C31. Inserción del programa en contextos académicos nacionales e internacionales | AF1: C32. Relaciones externas de profesores y estudiantes | AG1: C33. Habilidades comunicativas en una segunda lengua | AH1: C34. Formación para la investigación, desarrollo tecnológico, la innovación y la creación | AI1: C35. Compromiso con la investigación, desarrollo tecnológico, la innovación y la creación | AJ1: C36. Programas y servicios | AK1: C37. Participación y seguimiento | AL1: C38. Estrategias y recursos de apoyo a profesores | AM1: C39. Estrategias y recursos de apoyo a estudiantes | AN1: C40. Recursos bibliográficos y de información | AW1: F1. Proyecto Educativo del Programa e Identidad Institucional | AX1: F2. Estudiantes | AY1: F3. Profesores | AZ1: F4. Egresados | BA1: F5. Aspectos académicos y resultados de aprendizaje | BB1: F6. Permanencia y graduación | BC1: F7. Interacción con el entorno nacional e internacional | BD1: F8. Aportes de la investigación, la innovación, el desarrollo tecnológico y la creación, asociados al programa académico | BE1: F9. Bienestar de la comunidad académica del programa | BF1: F10. Medios educativos y ambientes de aprendizaje | BG1: F11. Organización, administración y financiación del programa académico | BH1: F12. Recursos físicos y tecnológicos
